<?xml version="1.0" ?>
<robot name="robot">    
<!--Check in RVIZ, joint trajectory controller-->

    <!-- <material name="white">
        <color rgba="1 1 1 1"/>
    </material>

    <material name="orange"> 
        <color rgba="1 0.3 0.1 1"/>
    </material>

    <material name="blue"> 
        <color rgba="0.2 0.2 1 1"/>
    </material>    

    <material name="black"> 
        <color rgba="0 0 0 1"/>
    </material>
    
    <material name="grey">
        <color rgba="0.6 0.6 0.6 1" />
    </material> -->

    <gazebo reference="base_link">
        <material>Gazebo/Black</material>
    </gazebo> 

    <gazebo reference="left_wheel">
        <material>Gazebo/Orange</material>
        <mu1>1</mu1>
        <mu2>1</mu2>
    </gazebo> 

    <gazebo reference="right_wheel">
        <material>Gazebo/Orange</material>
        <mu1>1</mu1>
        <mu2>1</mu2>
    </gazebo> 

    <gazebo reference="front_caster">
        <material>Gazebo/Blue</material>
        <mu1>0</mu1>
        <mu2>0</mu2>
    </gazebo> 

    <gazebo reference="back_caster">
        <material>Gazebo/Blue</material>
        <mu1>0</mu1>
        <mu2>0</mu2>
    </gazebo> 

    <gazebo reference="front_laser">
        <material>Gazebo/Grey</material>
    </gazebo> 

    <!-- Link - base_footprint -->
    <link name="base_footprint">
        <visual>
            <geometry>
                <cylinder radius="0.2" length="0.01"/> <!-- Thin base footprint-->
            </geometry>
            <origin xyz="0 0 0.005" rpy="0 0 0"/>
        </visual>
    </link>

    <!-- Joint - joint_base_footprint_to_base_link -->
    <joint name="joint_base_footprint_to_base_link" type="fixed">
        <origin xyz="0 0 0.15" rpy="0 0 0"/>
        <parent link="base_footprint"/>
        <child link="base_link"/>
    </joint>

    <!-- Link - base_link -->
    <link name="base_link">
        <inertial>
            <mass value="15" />
            <origin xyz="0 0 0.15" rpy="0 0 0"/>
            <inertia ixx="0.4625" ixy="0" ixz="0" iyy="0.4625" iyz="0" izz="0.625"/>
        </inertial>
        <visual>
            <geometry>
                <cylinder radius="0.25" length="0.3"/>
            </geometry>
        </visual>
        <collision>
            <geometry>
                <cylinder radius="0.25" length="0.3"/>
            </geometry>
        </collision>
    </link>

    <!-- Joint - left_wheel_joint -->
    <joint name="left_wheel_joint" type="continuous">
        <parent link="base_link"/>
        <child link="left_wheel"/>
        <!-- <origin xyz="0 0.2 -0.15" rpy="1.57 0 0"/> -->
        <origin xyz="0 0.2 -0.15" rpy="0 0 0"/>
        <axis rpy="0 0 0" xyz="0 1 0" />
        <limit effort="10000" velocity="1000" />
        <joint_properties damping="1.0" friction="1.0" />
    </joint>

    <!-- Link - left_wheel -->
    <link name="left_wheel">
        <inertial>
            <mass value="2.5" />
            <origin xyz="0 0.02 0 " rpy="0 0 0"/>
            <inertia ixx="0.00029" ixy="0" ixz="0" iyy="0.00031" iyz="0" izz="0.00029"/>
        </inertial>
        <visual>
            <origin xyz="0 0 0 " rpy="1.57 0 0"/>
            <geometry>
                <cylinder radius="0.025" length="0.04"/>
            </geometry>
        </visual>
        <collision>
            <origin xyz="0 0 0 " rpy="1.57 0 0"/>
            <geometry>
                <cylinder radius="0.025" length="0.04"/>
            </geometry>         
        </collision>
    </link>

    <!-- RIGHT WHEEL -->
    <!-- Joint - right_wheel_joint -->
    <joint name="right_wheel_joint" type="continuous">
        <parent link="base_link"/>
        <child link="right_wheel"/>
        <!-- <origin xyz="0 -0.2 -0.15" rpy="1.57 0 0"/> -->
        <origin xyz="0 -0.2 -0.15" rpy="0 0 0"/>
        <axis rpy="0 0 0" xyz="0 1 0" />
        <limit effort="10000" velocity="1000" />
        <joint_properties damping="1.0" friction="1.0" />
    </joint>

    <!-- Link - right_wheel -->
    <link name="right_wheel">
        <inertial>
            <mass value="2.5" />
            <origin xyz="0 0.02 0 " rpy="0 0 0"/>
            <inertia ixx="0.00029" ixy="0" ixz="0" iyy="0.00031" iyz="0" izz="0.00029"/>
        </inertial>
        <visual>
            <origin xyz="0 0 0 " rpy="1.57 0 0"/>
            <geometry>
                <cylinder radius="0.025" length="0.04"/>
            </geometry>
        </visual>
        <collision>
            <origin xyz="0 0 0 " rpy="1.57 0 0"/>
            <geometry>
                <cylinder radius="0.025" length="0.04"/>
            </geometry>
        </collision>
    </link>

    <!-- FRONT CASTER WHEEL -->
     <!-- Joint - base_link_front_caster_wheel -->
    <joint name="base_link_front_caster_wheel" type="fixed">
        <origin xyz="-0.1 0.0 -0.15" rpy="0 0 0" />
        <child link="front_caster" />
        <parent link="base_link" />
        <joint_properties friction="0" />
    </joint>

    <!-- Link - front_caster -->
    <link name="front_caster">
        <inertial>
            <mass value="2.5" />
            <origin xyz="0 0 0" rpy="0 0 0"/>
            <inertia ixx="0.00025" ixy="0" ixz="0" iyy="0.00025" iyz="0" izz="0.00025"/>
        </inertial>

        <!-- Caster Wheel -->
        <visual>
            <geometry>
                <sphere radius="0.025" />
            </geometry>
        </visual>
        <collision>
            <geometry>
                <sphere radius="0.025" />
            </geometry>
        </collision>
    </link>

    <!-- BACK CASTER WHEEL -->
     <!-- Joint - base_link_back_caster_wheel -->
    <joint name="base_link_back_caster_wheel" type="fixed">
        <origin xyz="0.1 0.0 -0.15" rpy="0 0 0" />
        <child link="back_caster" />
        <parent link="base_link" />
        <joint_properties friction="0" />
    </joint>    

    <!-- Link - back_caster -->
    <link name="back_caster">
        <inertial>
            <mass value="2.5" />
            <origin xyz="0 0 0" rpy="0 0 0"/>
            <inertia ixx="0.00025" ixy="0" ixz="0" iyy="0.00025" iyz="0" izz="0.00025"/>
        </inertial>

        <!-- Caster Wheel -->
        <visual>
            <geometry>
                <sphere radius="0.025" />
            </geometry>
            <material name="black" />
        </visual>
        <collision>
            <geometry>
                <sphere radius="0.025" />
            </geometry>
        </collision>
    </link>

    <!-- LASER -->
    <joint name="base_link_front_laser" type="fixed">
        <parent link="base_link"/>
        <child link="front_laser"/>
        <origin xyz="0.25 0 0.075" rpy="3.14 0 0"/>
        <joint_properties damping="1.0" friction="1.0" />
    </joint>

    <link name="front_laser">
        <!-- <inertial>
            <mass value="1"/>
            <origin xyz="0 0 0.025" rpy="0 0 0" />
            <inertia ixx="0.00083" ixy="0" ixz="0" iyy="0.00083" iyz="0" izz="0.00125"/>
        </inertial> -->

        <visual>
            <geometry>
                <cylinder radius="0.05" length="0.05"/>
            </geometry>
        </visual>
        <collision>
            <geometry>
                <cylinder radius="0.05" length="0.05"/>
            </geometry>
        </collision>
    </link>

    <!--DIFFERENTIAL DRIVE-->
<gazebo>
  <plugin name="differential_drive_controller" filename="libgazebo_ros_diff_drive.so">

    <alwaysOn>true</alwaysOn>

    <!-- Plugin update rate in Hz -->
    <updateRate>20</updateRate>

    <!-- Name of left joint, defaults to `left_joint` -->
    <leftJoint>left_wheel_joint</leftJoint>

    <!-- Name of right joint, defaults to `right_joint` -->
    <rightJoint>right_wheel_joint</rightJoint>

    <!-- The distance from the center of one wheel to the other, in meters, defaults to 0.34 m -->
    <wheelSeparation>0.44</wheelSeparation>

    <!-- Diameter of the wheels, in meters, defaults to 0.15 m -->
    <wheelDiameter>0.05</wheelDiameter>

    <!-- Maximum torque which the wheels can produce, in Nm, defaults to 5 Nm -->
    <wheelTorque>10</wheelTorque>

    <!-- Topic to receive geometry_msgs/Twist message commands, defaults to `cmd_vel` -->
    <commandTopic>cmd_vel</commandTopic>

    <!-- Topic to publish nav_msgs/Odometry messages, defaults to `odom` -->
    <odometryTopic>odom</odometryTopic>

    <!-- Odometry frame, defaults to `odom` -->
    <odometryFrame>odom</odometryFrame>

    <!-- Robot frame to calculate odometry from, defaults to `base_footprint` -->
    <robotBaseFrame>base_link</robotBaseFrame>

  </plugin>
</gazebo>

<!--LASER PLUGIN-->
<!-- hokuyo -->
<gazebo reference="front_laser">
    <sensor type="ray" name="head_hokuyo_sensor">
        <pose>0 0 0 0 0 0</pose>
        <visualize>false</visualize>
        <update_rate>20</update_rate>
        <ray>
        <scan>
            <horizontal>
            <samples>720</samples>
            <resolution>1</resolution>
            <min_angle>-1.570796</min_angle>
            <max_angle>1.570796</max_angle>
            </horizontal>
        </scan>
        <range>
            <min>0.20</min>
            <max>30.0</max>
            <resolution>0.01</resolution>
        </range>
        <noise>
            <type>gaussian</type>
            <!-- Noise parameters based on published spec for Hokuyo laser
                achieving "+-30mm" accuracy at range < 10m.  A mean of 0.0m and
                stddev of 0.01m will put 99.7% of samples within 0.03m of the true
                reading. -->
            <mean>0.0</mean>
            <stddev>0.01</stddev>
        </noise>
        </ray>
        <plugin name="gazebo_ros_head_hokuyo_controller" filename="libgazebo_ros_laser.so">
        <topicName>/scan</topicName>
        <frameName>front_laser</frameName>
        </plugin>
    </sensor>
</gazebo>


</robot>
